[2024-06-04T12:18:09.376+0000] {task_context_logger.py:104} ERROR - Executor reports task instance <TaskInstance: metrics_calculators.pipeline manual__2024-06-04T12:18:07.467800+00:00 [queued]> finished (failed) although the task says it's queued. (Info: None) Was the task killed externally?
