[2024-06-09T11:21:48.042+0000] {local_task_job_runner.py:120} INFO - ::group::Pre task execution logs
[2024-06-09T11:21:48.052+0000] {taskinstance.py:2076} INFO - Dependencies all met for dep_context=non-requeueable deps ti=<TaskInstance: metrics_calculator.cloud_function_task manual__2024-06-09T11:21:46.138624+00:00 [queued]>
[2024-06-09T11:21:48.056+0000] {taskinstance.py:2076} INFO - Dependencies all met for dep_context=requeueable deps ti=<TaskInstance: metrics_calculator.cloud_function_task manual__2024-06-09T11:21:46.138624+00:00 [queued]>
[2024-06-09T11:21:48.056+0000] {taskinstance.py:2306} INFO - Starting attempt 1 of 2
[2024-06-09T11:21:48.063+0000] {taskinstance.py:2330} INFO - Executing <Task(CloudFunctionInvokeFunctionOperator): cloud_function_task> on 2024-06-09 11:21:46.138624+00:00
[2024-06-09T11:21:48.067+0000] {warnings.py:110} WARNING - /home/***/.local/lib/python3.12/site-packages/***/task/task_runner/standard_task_runner.py:61: DeprecationWarning: This process (pid=661) is multi-threaded, use of fork() may lead to deadlocks in the child.
  pid = os.fork()

[2024-06-09T11:21:48.068+0000] {standard_task_runner.py:63} INFO - Started process 662 to run task
[2024-06-09T11:21:48.069+0000] {standard_task_runner.py:90} INFO - Running: ['***', 'tasks', 'run', 'metrics_calculator', 'cloud_function_task', 'manual__2024-06-09T11:21:46.138624+00:00', '--job-id', '13', '--raw', '--subdir', 'DAGS_FOLDER/dag_reader.py', '--cfg-path', '/tmp/tmpk8u_dzd5']
[2024-06-09T11:21:48.071+0000] {standard_task_runner.py:91} INFO - Job 13: Subtask cloud_function_task
[2024-06-09T11:21:48.099+0000] {task_command.py:426} INFO - Running <TaskInstance: metrics_calculator.cloud_function_task manual__2024-06-09T11:21:46.138624+00:00 [running]> on host d7fa402d9e56
[2024-06-09T11:21:48.179+0000] {taskinstance.py:2648} INFO - Exporting env vars: AIRFLOW_CTX_DAG_OWNER='mehdizarria' AIRFLOW_CTX_DAG_ID='metrics_calculator' AIRFLOW_CTX_TASK_ID='cloud_function_task' AIRFLOW_CTX_EXECUTION_DATE='2024-06-09T11:21:46.138624+00:00' AIRFLOW_CTX_TRY_NUMBER='1' AIRFLOW_CTX_DAG_RUN_ID='manual__2024-06-09T11:21:46.138624+00:00'
[2024-06-09T11:21:48.181+0000] {taskinstance.py:430} INFO - ::endgroup::
[2024-06-09T11:21:48.194+0000] {connection.py:274} WARNING - Connection schemes (type: google_cloud_platform) shall not contain '_' according to RFC3986.
[2024-06-09T11:21:48.196+0000] {base.py:84} INFO - Using connection ID 'gcp_connection' for task execution.
[2024-06-09T11:21:48.197+0000] {functions.py:471} INFO - Calling function cloud-function-test.
[2024-06-09T11:21:48.502+0000] {taskinstance.py:441} INFO - ::group::Post task execution logs
[2024-06-09T11:21:48.511+0000] {taskinstance.py:2905} ERROR - Task failed with exception
Traceback (most recent call last):
  File "/home/airflow/.local/lib/python3.12/site-packages/airflow/models/taskinstance.py", line 465, in _execute_task
    result = _execute_callable(context=context, **execute_callable_kwargs)
             ^^^^^^^^^^^^^^^^^^^^^^^^^^^^^^^^^^^^^^^^^^^^^^^^^^^^^^^^^^^^^
  File "/home/airflow/.local/lib/python3.12/site-packages/airflow/models/taskinstance.py", line 432, in _execute_callable
    return execute_callable(context=context, **execute_callable_kwargs)
           ^^^^^^^^^^^^^^^^^^^^^^^^^^^^^^^^^^^^^^^^^^^^^^^^^^^^^^^^^^^^
  File "/home/airflow/.local/lib/python3.12/site-packages/airflow/models/baseoperator.py", line 400, in wrapper
    return func(self, *args, **kwargs)
           ^^^^^^^^^^^^^^^^^^^^^^^^^^^
  File "/home/airflow/.local/lib/python3.12/site-packages/airflow/providers/google/cloud/operators/functions.py", line 472, in execute
    result = hook.call_function(
             ^^^^^^^^^^^^^^^^^^^
  File "/home/airflow/.local/lib/python3.12/site-packages/airflow/providers/google/common/hooks/base_google.py", line 486, in inner_wrapper
    return func(self, *args, **kwargs)
           ^^^^^^^^^^^^^^^^^^^^^^^^^^^
  File "/home/airflow/.local/lib/python3.12/site-packages/airflow/providers/google/cloud/hooks/functions.py", line 199, in call_function
    response = operation.execute(num_retries=self.num_retries)
               ^^^^^^^^^^^^^^^^^^^^^^^^^^^^^^^^^^^^^^^^^^^^^^^
  File "/home/airflow/.local/lib/python3.12/site-packages/googleapiclient/_helpers.py", line 130, in positional_wrapper
    return wrapped(*args, **kwargs)
           ^^^^^^^^^^^^^^^^^^^^^^^^
  File "/home/airflow/.local/lib/python3.12/site-packages/googleapiclient/http.py", line 938, in execute
    raise HttpError(resp, content, uri=self.uri)
googleapiclient.errors.HttpError: <HttpError 404 when requesting https://cloudfunctions.googleapis.com/v1/projects/mz-data-manipulation/locations/europe-west1/functions/cloud-function-test:call?alt=json returned "Function cloud-function-test in region europe-west1 in project mz-data-manipulation does not exist". Details: "Function cloud-function-test in region europe-west1 in project mz-data-manipulation does not exist">
[2024-06-09T11:21:48.533+0000] {taskinstance.py:1206} INFO - Marking task as UP_FOR_RETRY. dag_id=metrics_calculator, task_id=cloud_function_task, run_id=manual__2024-06-09T11:21:46.138624+00:00, execution_date=20240609T112146, start_date=20240609T112148, end_date=20240609T112148
[2024-06-09T11:21:48.541+0000] {standard_task_runner.py:110} ERROR - Failed to execute job 13 for task cloud_function_task (<HttpError 404 when requesting https://cloudfunctions.googleapis.com/v1/projects/mz-data-manipulation/locations/europe-west1/functions/cloud-function-test:call?alt=json returned "Function cloud-function-test in region europe-west1 in project mz-data-manipulation does not exist". Details: "Function cloud-function-test in region europe-west1 in project mz-data-manipulation does not exist">; 662)
[2024-06-09T11:21:48.552+0000] {local_task_job_runner.py:240} INFO - Task exited with return code 1
[2024-06-09T11:21:48.570+0000] {taskinstance.py:3498} INFO - 0 downstream tasks scheduled from follow-on schedule check
[2024-06-09T11:21:48.571+0000] {local_task_job_runner.py:222} INFO - ::endgroup::
