[2024-06-04T12:29:37.202+0000] {local_task_job_runner.py:120} INFO - ::group::Pre task execution logs
[2024-06-04T12:29:37.213+0000] {taskinstance.py:2076} INFO - Dependencies all met for dep_context=non-requeueable deps ti=<TaskInstance: metrics_calculators2.run_after_loop manual__2024-06-04T12:29:35.134022+00:00 [queued]>
[2024-06-04T12:29:37.216+0000] {taskinstance.py:2076} INFO - Dependencies all met for dep_context=requeueable deps ti=<TaskInstance: metrics_calculators2.run_after_loop manual__2024-06-04T12:29:35.134022+00:00 [queued]>
[2024-06-04T12:29:37.216+0000] {taskinstance.py:2306} INFO - Starting attempt 1 of 2
[2024-06-04T12:29:37.222+0000] {taskinstance.py:2330} INFO - Executing <Task(BashOperator): run_after_loop> on 2024-06-04 12:29:35.134022+00:00
[2024-06-04T12:29:37.227+0000] {warnings.py:110} WARNING - /home/***/.local/lib/python3.12/site-packages/***/task/task_runner/standard_task_runner.py:61: DeprecationWarning: This process (pid=12246) is multi-threaded, use of fork() may lead to deadlocks in the child.
  pid = os.fork()

[2024-06-04T12:29:37.228+0000] {standard_task_runner.py:63} INFO - Started process 12248 to run task
[2024-06-04T12:29:37.228+0000] {standard_task_runner.py:90} INFO - Running: ['***', 'tasks', 'run', 'metrics_calculators2', 'run_after_loop', 'manual__2024-06-04T12:29:35.134022+00:00', '--job-id', '31', '--raw', '--subdir', 'DAGS_FOLDER/dag_reader.py', '--cfg-path', '/tmp/tmpoe87hmfv']
[2024-06-04T12:29:37.229+0000] {standard_task_runner.py:91} INFO - Job 31: Subtask run_after_loop
[2024-06-04T12:29:37.255+0000] {task_command.py:426} INFO - Running <TaskInstance: metrics_calculators2.run_after_loop manual__2024-06-04T12:29:35.134022+00:00 [running]> on host f291404afb14
[2024-06-04T12:29:37.300+0000] {taskinstance.py:2648} INFO - Exporting env vars: AIRFLOW_CTX_DAG_OWNER='mehdizarria' AIRFLOW_CTX_DAG_ID='metrics_calculators2' AIRFLOW_CTX_TASK_ID='run_after_loop' AIRFLOW_CTX_EXECUTION_DATE='2024-06-04T12:29:35.134022+00:00' AIRFLOW_CTX_TRY_NUMBER='1' AIRFLOW_CTX_DAG_RUN_ID='manual__2024-06-04T12:29:35.134022+00:00'
[2024-06-04T12:29:37.302+0000] {taskinstance.py:430} INFO - ::endgroup::
[2024-06-04T12:29:37.302+0000] {subprocess.py:63} INFO - Tmp dir root location: /tmp
[2024-06-04T12:29:37.303+0000] {subprocess.py:75} INFO - Running command: ['/usr/bin/bash', '-c', 'cd /opt/***/Data && ls']
[2024-06-04T12:29:37.317+0000] {subprocess.py:86} INFO - Output:
[2024-06-04T12:29:37.319+0000] {subprocess.py:93} INFO - /usr/bin/bash: line 1: cd: /opt/***/Data: No such file or directory
[2024-06-04T12:29:37.319+0000] {subprocess.py:97} INFO - Command exited with return code 1
[2024-06-04T12:29:37.319+0000] {taskinstance.py:441} INFO - ::group::Post task execution logs
[2024-06-04T12:29:37.381+0000] {taskinstance.py:2905} ERROR - Task failed with exception
Traceback (most recent call last):
  File "/home/airflow/.local/lib/python3.12/site-packages/airflow/models/taskinstance.py", line 465, in _execute_task
    result = _execute_callable(context=context, **execute_callable_kwargs)
             ^^^^^^^^^^^^^^^^^^^^^^^^^^^^^^^^^^^^^^^^^^^^^^^^^^^^^^^^^^^^^
  File "/home/airflow/.local/lib/python3.12/site-packages/airflow/models/taskinstance.py", line 432, in _execute_callable
    return execute_callable(context=context, **execute_callable_kwargs)
           ^^^^^^^^^^^^^^^^^^^^^^^^^^^^^^^^^^^^^^^^^^^^^^^^^^^^^^^^^^^^
  File "/home/airflow/.local/lib/python3.12/site-packages/airflow/models/baseoperator.py", line 400, in wrapper
    return func(self, *args, **kwargs)
           ^^^^^^^^^^^^^^^^^^^^^^^^^^^
  File "/home/airflow/.local/lib/python3.12/site-packages/airflow/operators/bash.py", line 243, in execute
    raise AirflowException(
airflow.exceptions.AirflowException: Bash command failed. The command returned a non-zero exit code 1.
[2024-06-04T12:29:37.390+0000] {taskinstance.py:1206} INFO - Marking task as UP_FOR_RETRY. dag_id=metrics_calculators2, task_id=run_after_loop, run_id=manual__2024-06-04T12:29:35.134022+00:00, execution_date=20240604T122935, start_date=20240604T122937, end_date=20240604T122937
[2024-06-04T12:29:37.406+0000] {standard_task_runner.py:110} ERROR - Failed to execute job 31 for task run_after_loop (Bash command failed. The command returned a non-zero exit code 1.; 12248)
[2024-06-04T12:29:37.417+0000] {local_task_job_runner.py:240} INFO - Task exited with return code 1
[2024-06-04T12:29:37.434+0000] {taskinstance.py:3498} INFO - 0 downstream tasks scheduled from follow-on schedule check
[2024-06-04T12:29:37.436+0000] {local_task_job_runner.py:222} INFO - ::endgroup::
