[2024-06-04T10:29:21.130+0000] {local_task_job_runner.py:120} INFO - ::group::Pre task execution logs
[2024-06-04T10:29:21.141+0000] {taskinstance.py:2076} INFO - Dependencies all met for dep_context=non-requeueable deps ti=<TaskInstance: metrics_calculator.read_files manual__2024-06-04T10:29:18.158293+00:00 [queued]>
[2024-06-04T10:29:21.145+0000] {taskinstance.py:2076} INFO - Dependencies all met for dep_context=requeueable deps ti=<TaskInstance: metrics_calculator.read_files manual__2024-06-04T10:29:18.158293+00:00 [queued]>
[2024-06-04T10:29:21.145+0000] {taskinstance.py:2306} INFO - Starting attempt 1 of 2
[2024-06-04T10:29:21.150+0000] {taskinstance.py:2330} INFO - Executing <Task(PythonOperator): read_files> on 2024-06-04 10:29:18.158293+00:00
[2024-06-04T10:29:21.154+0000] {warnings.py:110} WARNING - /home/***/.local/lib/python3.12/site-packages/***/task/task_runner/standard_task_runner.py:61: DeprecationWarning: This process (pid=10576) is multi-threaded, use of fork() may lead to deadlocks in the child.
  pid = os.fork()

[2024-06-04T10:29:21.155+0000] {standard_task_runner.py:63} INFO - Started process 10578 to run task
[2024-06-04T10:29:21.155+0000] {standard_task_runner.py:90} INFO - Running: ['***', 'tasks', 'run', 'metrics_calculator', 'read_files', 'manual__2024-06-04T10:29:18.158293+00:00', '--job-id', '18', '--raw', '--subdir', 'DAGS_FOLDER/dag_reader.py', '--cfg-path', '/tmp/tmpzq2pcczp']
[2024-06-04T10:29:21.157+0000] {standard_task_runner.py:91} INFO - Job 18: Subtask read_files
[2024-06-04T10:29:21.187+0000] {task_command.py:426} INFO - Running <TaskInstance: metrics_calculator.read_files manual__2024-06-04T10:29:18.158293+00:00 [running]> on host f291404afb14
[2024-06-04T10:29:21.263+0000] {taskinstance.py:2648} INFO - Exporting env vars: AIRFLOW_CTX_DAG_OWNER='mehdizarria' AIRFLOW_CTX_DAG_ID='metrics_calculator' AIRFLOW_CTX_TASK_ID='read_files' AIRFLOW_CTX_EXECUTION_DATE='2024-06-04T10:29:18.158293+00:00' AIRFLOW_CTX_TRY_NUMBER='1' AIRFLOW_CTX_DAG_RUN_ID='manual__2024-06-04T10:29:18.158293+00:00'
[2024-06-04T10:29:21.267+0000] {taskinstance.py:430} INFO - ::endgroup::
[2024-06-04T10:29:21.277+0000] {logging_mixin.py:188} WARNING - --- Logging error ---
[2024-06-04T10:29:21.281+0000] {logging_mixin.py:188} WARNING - Traceback (most recent call last):
[2024-06-04T10:29:21.282+0000] {logging_mixin.py:188} WARNING -   File "/usr/local/lib/python3.12/logging/__init__.py", line 1160, in emit
    msg = self.format(record)
          ^^^^^^^^^^^^^^^^^^^
[2024-06-04T10:29:21.282+0000] {logging_mixin.py:188} WARNING -   File "/usr/local/lib/python3.12/logging/__init__.py", line 999, in format
    return fmt.format(record)
           ^^^^^^^^^^^^^^^^^^
[2024-06-04T10:29:21.282+0000] {logging_mixin.py:188} WARNING -   File "/usr/local/lib/python3.12/logging/__init__.py", line 703, in format
    record.message = record.getMessage()
                     ^^^^^^^^^^^^^^^^^^^
[2024-06-04T10:29:21.283+0000] {logging_mixin.py:188} WARNING -   File "/usr/local/lib/python3.12/logging/__init__.py", line 392, in getMessage
    msg = msg % self.args
          ~~~~^~~~~~~~~~~
[2024-06-04T10:29:21.283+0000] {logging_mixin.py:188} WARNING -   File "/home/***/.local/lib/python3.12/site-packages/polars/lazyframe/frame.py", line 565, in __str__
    {self.explain(optimized=False)}\
     ^^^^^^^^^^^^^^^^^^^^^^^^^^^^^
[2024-06-04T10:29:21.283+0000] {logging_mixin.py:188} WARNING -   File "/home/***/.local/lib/python3.12/site-packages/polars/lazyframe/frame.py", line 1024, in explain
    return self._ldf.describe_plan()
           ^^^^^^^^^^^^^^^^^^^^^^^^^
[2024-06-04T10:29:21.283+0000] {logging_mixin.py:188} WARNING - FileNotFoundError: No such file or directory (os error 2): ../Data/source/2013/*.csv
[2024-06-04T10:29:21.284+0000] {logging_mixin.py:188} WARNING - Call stack:
[2024-06-04T10:29:21.291+0000] {logging_mixin.py:188} WARNING -   File "/home/***/.local/bin/***", line 8, in <module>
    sys.exit(main())
[2024-06-04T10:29:21.291+0000] {logging_mixin.py:188} WARNING -   File "/home/***/.local/lib/python3.12/site-packages/***/__main__.py", line 58, in main
    args.func(args)
[2024-06-04T10:29:21.292+0000] {logging_mixin.py:188} WARNING -   File "/home/***/.local/lib/python3.12/site-packages/***/cli/cli_config.py", line 49, in command
    return func(*args, **kwargs)
[2024-06-04T10:29:21.292+0000] {logging_mixin.py:188} WARNING -   File "/home/***/.local/lib/python3.12/site-packages/***/utils/cli.py", line 114, in wrapper
    return f(*args, **kwargs)
[2024-06-04T10:29:21.292+0000] {logging_mixin.py:188} WARNING -   File "/home/***/.local/lib/python3.12/site-packages/***/providers/celery/cli/celery_command.py", line 61, in wrapper
    providers_configuration_loaded(func)(*args, **kwargs)
[2024-06-04T10:29:21.293+0000] {logging_mixin.py:188} WARNING -   File "/home/***/.local/lib/python3.12/site-packages/***/utils/providers_configuration_loader.py", line 55, in wrapped_function
    return func(*args, **kwargs)
[2024-06-04T10:29:21.293+0000] {logging_mixin.py:188} WARNING -   File "/home/***/.local/lib/python3.12/site-packages/***/providers/celery/cli/celery_command.py", line 234, in worker
    _run_command_with_daemon_option(
[2024-06-04T10:29:21.293+0000] {logging_mixin.py:188} WARNING -   File "/home/***/.local/lib/python3.12/site-packages/***/providers/celery/cli/celery_command.py", line 47, in _run_command_with_daemon_option
    run_command_with_daemon_option(*args, **kwargs)
[2024-06-04T10:29:21.293+0000] {logging_mixin.py:188} WARNING -   File "/home/***/.local/lib/python3.12/site-packages/***/cli/commands/daemon_utils.py", line 85, in run_command_with_daemon_option
    callback()
[2024-06-04T10:29:21.293+0000] {logging_mixin.py:188} WARNING -   File "/home/***/.local/lib/python3.12/site-packages/***/providers/celery/cli/celery_command.py", line 227, in run_celery_worker
    celery_app.worker_main(options)
[2024-06-04T10:29:21.294+0000] {logging_mixin.py:188} WARNING -   File "/home/***/.local/lib/python3.12/site-packages/celery/app/base.py", line 391, in worker_main
    self.start(argv=argv)
[2024-06-04T10:29:21.294+0000] {logging_mixin.py:188} WARNING -   File "/home/***/.local/lib/python3.12/site-packages/celery/app/base.py", line 371, in start
    celery.main(args=argv, standalone_mode=False)
[2024-06-04T10:29:21.294+0000] {logging_mixin.py:188} WARNING -   File "/home/***/.local/lib/python3.12/site-packages/click/core.py", line 1078, in main
    rv = self.invoke(ctx)
[2024-06-04T10:29:21.294+0000] {logging_mixin.py:188} WARNING -   File "/home/***/.local/lib/python3.12/site-packages/click/core.py", line 1688, in invoke
    return _process_result(sub_ctx.command.invoke(sub_ctx))
[2024-06-04T10:29:21.294+0000] {logging_mixin.py:188} WARNING -   File "/home/***/.local/lib/python3.12/site-packages/click/core.py", line 1434, in invoke
    return ctx.invoke(self.callback, **ctx.params)
[2024-06-04T10:29:21.295+0000] {logging_mixin.py:188} WARNING -   File "/home/***/.local/lib/python3.12/site-packages/click/core.py", line 783, in invoke
    return __callback(*args, **kwargs)
[2024-06-04T10:29:21.295+0000] {logging_mixin.py:188} WARNING -   File "/home/***/.local/lib/python3.12/site-packages/click/decorators.py", line 33, in new_func
    return f(get_current_context(), *args, **kwargs)
[2024-06-04T10:29:21.295+0000] {logging_mixin.py:188} WARNING -   File "/home/***/.local/lib/python3.12/site-packages/celery/bin/base.py", line 135, in caller
    return f(ctx, *args, **kwargs)
[2024-06-04T10:29:21.295+0000] {logging_mixin.py:188} WARNING -   File "/home/***/.local/lib/python3.12/site-packages/celery/bin/worker.py", line 356, in worker
    worker.start()
[2024-06-04T10:29:21.295+0000] {logging_mixin.py:188} WARNING -   File "/home/***/.local/lib/python3.12/site-packages/celery/worker/worker.py", line 202, in start
    self.blueprint.start(self)
[2024-06-04T10:29:21.296+0000] {logging_mixin.py:188} WARNING -   File "/home/***/.local/lib/python3.12/site-packages/celery/bootsteps.py", line 116, in start
    step.start(parent)
[2024-06-04T10:29:21.296+0000] {logging_mixin.py:188} WARNING -   File "/home/***/.local/lib/python3.12/site-packages/celery/bootsteps.py", line 365, in start
    return self.obj.start()
[2024-06-04T10:29:21.296+0000] {logging_mixin.py:188} WARNING -   File "/home/***/.local/lib/python3.12/site-packages/celery/concurrency/base.py", line 130, in start
    self.on_start()
[2024-06-04T10:29:21.296+0000] {logging_mixin.py:188} WARNING -   File "/home/***/.local/lib/python3.12/site-packages/celery/concurrency/prefork.py", line 109, in on_start
    P = self._pool = Pool(processes=self.limit,
[2024-06-04T10:29:21.297+0000] {logging_mixin.py:188} WARNING -   File "/home/***/.local/lib/python3.12/site-packages/celery/concurrency/asynpool.py", line 464, in __init__
    super().__init__(processes, *args, **kwargs)
[2024-06-04T10:29:21.297+0000] {logging_mixin.py:188} WARNING -   File "/home/***/.local/lib/python3.12/site-packages/billiard/pool.py", line 1045, in __init__
    self._create_worker_process(i)
[2024-06-04T10:29:21.297+0000] {logging_mixin.py:188} WARNING -   File "/home/***/.local/lib/python3.12/site-packages/celery/concurrency/asynpool.py", line 482, in _create_worker_process
    return super()._create_worker_process(i)
[2024-06-04T10:29:21.297+0000] {logging_mixin.py:188} WARNING -   File "/home/***/.local/lib/python3.12/site-packages/billiard/pool.py", line 1157, in _create_worker_process
    w.start()
[2024-06-04T10:29:21.297+0000] {logging_mixin.py:188} WARNING -   File "/home/***/.local/lib/python3.12/site-packages/billiard/process.py", line 120, in start
    self._popen = self._Popen(self)
[2024-06-04T10:29:21.297+0000] {logging_mixin.py:188} WARNING -   File "/home/***/.local/lib/python3.12/site-packages/billiard/context.py", line 331, in _Popen
    return Popen(process_obj)
[2024-06-04T10:29:21.298+0000] {logging_mixin.py:188} WARNING -   File "/home/***/.local/lib/python3.12/site-packages/billiard/popen_fork.py", line 22, in __init__
    self._launch(process_obj)
[2024-06-04T10:29:21.298+0000] {logging_mixin.py:188} WARNING -   File "/home/***/.local/lib/python3.12/site-packages/billiard/popen_fork.py", line 77, in _launch
    code = process_obj._bootstrap()
[2024-06-04T10:29:21.298+0000] {logging_mixin.py:188} WARNING -   File "/home/***/.local/lib/python3.12/site-packages/billiard/process.py", line 323, in _bootstrap
    self.run()
[2024-06-04T10:29:21.298+0000] {logging_mixin.py:188} WARNING -   File "/home/***/.local/lib/python3.12/site-packages/billiard/process.py", line 110, in run
    self._target(*self._args, **self._kwargs)
[2024-06-04T10:29:21.299+0000] {logging_mixin.py:188} WARNING -   File "/home/***/.local/lib/python3.12/site-packages/billiard/pool.py", line 291, in __call__
    sys.exit(self.workloop(pid=pid))
[2024-06-04T10:29:21.299+0000] {logging_mixin.py:188} WARNING -   File "/home/***/.local/lib/python3.12/site-packages/billiard/pool.py", line 361, in workloop
    result = (True, prepare_result(fun(*args, **kwargs)))
[2024-06-04T10:29:21.299+0000] {logging_mixin.py:188} WARNING -   File "/home/***/.local/lib/python3.12/site-packages/celery/app/trace.py", line 651, in fast_trace_task
    R, I, T, Rstr = tasks[task].__trace__(
[2024-06-04T10:29:21.299+0000] {logging_mixin.py:188} WARNING -   File "/home/***/.local/lib/python3.12/site-packages/celery/app/trace.py", line 453, in trace_task
    R = retval = fun(*args, **kwargs)
[2024-06-04T10:29:21.300+0000] {logging_mixin.py:188} WARNING -   File "/home/***/.local/lib/python3.12/site-packages/celery/app/trace.py", line 736, in __protected_call__
    return self.run(*args, **kwargs)
[2024-06-04T10:29:21.300+0000] {logging_mixin.py:188} WARNING -   File "/home/***/.local/lib/python3.12/site-packages/***/providers/celery/executors/celery_executor_utils.py", line 136, in execute_command
    _execute_in_fork(command_to_exec, celery_task_id)
[2024-06-04T10:29:21.300+0000] {logging_mixin.py:188} WARNING -   File "/home/***/.local/lib/python3.12/site-packages/***/providers/celery/executors/celery_executor_utils.py", line 172, in _execute_in_fork
    args.func(args)
[2024-06-04T10:29:21.300+0000] {logging_mixin.py:188} WARNING -   File "/home/***/.local/lib/python3.12/site-packages/***/cli/cli_config.py", line 49, in command
    return func(*args, **kwargs)
[2024-06-04T10:29:21.300+0000] {logging_mixin.py:188} WARNING -   File "/home/***/.local/lib/python3.12/site-packages/***/utils/cli.py", line 114, in wrapper
    return f(*args, **kwargs)
[2024-06-04T10:29:21.301+0000] {logging_mixin.py:188} WARNING -   File "/home/***/.local/lib/python3.12/site-packages/***/cli/commands/task_command.py", line 441, in task_run
    task_return_code = _run_task_by_selected_method(args, _dag, ti)
[2024-06-04T10:29:21.301+0000] {logging_mixin.py:188} WARNING -   File "/home/***/.local/lib/python3.12/site-packages/***/cli/commands/task_command.py", line 219, in _run_task_by_selected_method
    return _run_task_by_local_task_job(args, ti)
[2024-06-04T10:29:21.301+0000] {logging_mixin.py:188} WARNING -   File "/home/***/.local/lib/python3.12/site-packages/***/cli/commands/task_command.py", line 281, in _run_task_by_local_task_job
    ret = run_job(job=job_runner.job, execute_callable=job_runner._execute)
[2024-06-04T10:29:21.301+0000] {logging_mixin.py:188} WARNING -   File "/home/***/.local/lib/python3.12/site-packages/***/utils/session.py", line 79, in wrapper
    return func(*args, session=session, **kwargs)
[2024-06-04T10:29:21.301+0000] {logging_mixin.py:188} WARNING -   File "/home/***/.local/lib/python3.12/site-packages/***/jobs/job.py", line 402, in run_job
    return execute_job(job, execute_callable=execute_callable)
[2024-06-04T10:29:21.301+0000] {logging_mixin.py:188} WARNING -   File "/home/***/.local/lib/python3.12/site-packages/***/jobs/job.py", line 431, in execute_job
    ret = execute_callable()
[2024-06-04T10:29:21.302+0000] {logging_mixin.py:188} WARNING -   File "/home/***/.local/lib/python3.12/site-packages/***/jobs/local_task_job_runner.py", line 168, in _execute
    self.task_runner.start()
[2024-06-04T10:29:21.302+0000] {logging_mixin.py:188} WARNING -   File "/home/***/.local/lib/python3.12/site-packages/***/task/task_runner/standard_task_runner.py", line 51, in start
    self.process = self._start_by_fork()
[2024-06-04T10:29:21.303+0000] {logging_mixin.py:188} WARNING -   File "/home/***/.local/lib/python3.12/site-packages/***/task/task_runner/standard_task_runner.py", line 103, in _start_by_fork
    ret = args.func(args, dag=self.dag)
[2024-06-04T10:29:21.303+0000] {logging_mixin.py:188} WARNING -   File "/home/***/.local/lib/python3.12/site-packages/***/cli/cli_config.py", line 49, in command
    return func(*args, **kwargs)
[2024-06-04T10:29:21.304+0000] {logging_mixin.py:188} WARNING -   File "/home/***/.local/lib/python3.12/site-packages/***/utils/cli.py", line 114, in wrapper
    return f(*args, **kwargs)
[2024-06-04T10:29:21.306+0000] {logging_mixin.py:188} WARNING -   File "/home/***/.local/lib/python3.12/site-packages/***/cli/commands/task_command.py", line 441, in task_run
    task_return_code = _run_task_by_selected_method(args, _dag, ti)
[2024-06-04T10:29:21.309+0000] {logging_mixin.py:188} WARNING -   File "/home/***/.local/lib/python3.12/site-packages/***/cli/commands/task_command.py", line 221, in _run_task_by_selected_method
    return _run_raw_task(args, ti)
[2024-06-04T10:29:21.310+0000] {logging_mixin.py:188} WARNING -   File "/home/***/.local/lib/python3.12/site-packages/***/cli/commands/task_command.py", line 300, in _run_raw_task
    return ti._run_raw_task(
[2024-06-04T10:29:21.310+0000] {logging_mixin.py:188} WARNING -   File "/home/***/.local/lib/python3.12/site-packages/***/utils/session.py", line 79, in wrapper
    return func(*args, session=session, **kwargs)
[2024-06-04T10:29:21.311+0000] {logging_mixin.py:188} WARNING -   File "/home/***/.local/lib/python3.12/site-packages/***/models/taskinstance.py", line 2479, in _run_raw_task
    self._execute_task_with_callbacks(context, test_mode, session=session)
[2024-06-04T10:29:21.313+0000] {logging_mixin.py:188} WARNING -   File "/home/***/.local/lib/python3.12/site-packages/***/models/taskinstance.py", line 2676, in _execute_task_with_callbacks
    result = self._execute_task(context, task_orig)
[2024-06-04T10:29:21.314+0000] {logging_mixin.py:188} WARNING -   File "/home/***/.local/lib/python3.12/site-packages/***/models/taskinstance.py", line 2701, in _execute_task
    return _execute_task(self, context, task_orig)
[2024-06-04T10:29:21.315+0000] {logging_mixin.py:188} WARNING -   File "/home/***/.local/lib/python3.12/site-packages/***/models/taskinstance.py", line 465, in _execute_task
    result = _execute_callable(context=context, **execute_callable_kwargs)
[2024-06-04T10:29:21.315+0000] {logging_mixin.py:188} WARNING -   File "/home/***/.local/lib/python3.12/site-packages/***/models/taskinstance.py", line 432, in _execute_callable
    return execute_callable(context=context, **execute_callable_kwargs)
[2024-06-04T10:29:21.315+0000] {logging_mixin.py:188} WARNING -   File "/home/***/.local/lib/python3.12/site-packages/***/models/baseoperator.py", line 400, in wrapper
    return func(self, *args, **kwargs)
[2024-06-04T10:29:21.316+0000] {logging_mixin.py:188} WARNING -   File "/home/***/.local/lib/python3.12/site-packages/***/operators/python.py", line 237, in execute
    self.log.info("Done. Returned value was: %s", return_value)
[2024-06-04T10:29:21.318+0000] {logging_mixin.py:188} WARNING -   File "/usr/local/lib/python3.12/logging/__init__.py", line 1539, in info
    self._log(INFO, msg, args, **kwargs)
[2024-06-04T10:29:21.319+0000] {logging_mixin.py:188} WARNING -   File "/usr/local/lib/python3.12/logging/__init__.py", line 1684, in _log
    self.handle(record)
[2024-06-04T10:29:21.320+0000] {logging_mixin.py:188} WARNING -   File "/usr/local/lib/python3.12/logging/__init__.py", line 1700, in handle
    self.callHandlers(record)
[2024-06-04T10:29:21.320+0000] {logging_mixin.py:188} WARNING -   File "/usr/local/lib/python3.12/logging/__init__.py", line 1762, in callHandlers
    hdlr.handle(record)
[2024-06-04T10:29:21.320+0000] {logging_mixin.py:188} WARNING -   File "/usr/local/lib/python3.12/logging/__init__.py", line 1028, in handle
    self.emit(record)
[2024-06-04T10:29:21.320+0000] {logging_mixin.py:188} WARNING -   File "/home/***/.local/lib/python3.12/site-packages/***/utils/log/file_task_handler.py", line 248, in emit
    self.handler.emit(record)
[2024-06-04T10:29:21.321+0000] {logging_mixin.py:188} WARNING - Message: 'Done. Returned value was: %s'
Arguments: (<LazyFrame at 0xFFFF99EF4500>,)
[2024-06-04T10:29:21.321+0000] {taskinstance.py:441} INFO - ::group::Post task execution logs
[2024-06-04T10:29:21.340+0000] {taskinstance.py:1206} INFO - Marking task as SUCCESS. dag_id=metrics_calculator, task_id=read_files, run_id=manual__2024-06-04T10:29:18.158293+00:00, execution_date=20240604T102918, start_date=20240604T102921, end_date=20240604T102921
[2024-06-04T10:29:21.378+0000] {local_task_job_runner.py:240} INFO - Task exited with return code 0
[2024-06-04T10:29:21.389+0000] {taskinstance.py:3498} INFO - 0 downstream tasks scheduled from follow-on schedule check
[2024-06-04T10:29:21.390+0000] {local_task_job_runner.py:222} INFO - ::endgroup::
