[2024-06-09T10:56:50.812+0000] {local_task_job_runner.py:120} INFO - ::group::Pre task execution logs
[2024-06-09T10:56:50.822+0000] {taskinstance.py:2076} INFO - Dependencies all met for dep_context=non-requeueable deps ti=<TaskInstance: metrics_calculator.cloud_function_task manual__2024-06-09T10:56:47.372616+00:00 [queued]>
[2024-06-09T10:56:50.826+0000] {taskinstance.py:2076} INFO - Dependencies all met for dep_context=requeueable deps ti=<TaskInstance: metrics_calculator.cloud_function_task manual__2024-06-09T10:56:47.372616+00:00 [queued]>
[2024-06-09T10:56:50.826+0000] {taskinstance.py:2306} INFO - Starting attempt 1 of 2
[2024-06-09T10:56:50.832+0000] {taskinstance.py:2330} INFO - Executing <Task(CloudFunctionInvokeFunctionOperator): cloud_function_task> on 2024-06-09 10:56:47.372616+00:00
[2024-06-09T10:56:50.838+0000] {warnings.py:110} WARNING - /home/***/.local/lib/python3.12/site-packages/***/task/task_runner/standard_task_runner.py:61: DeprecationWarning: This process (pid=317) is multi-threaded, use of fork() may lead to deadlocks in the child.
  pid = os.fork()

[2024-06-09T10:56:50.839+0000] {standard_task_runner.py:63} INFO - Started process 318 to run task
[2024-06-09T10:56:50.839+0000] {standard_task_runner.py:90} INFO - Running: ['***', 'tasks', 'run', 'metrics_calculator', 'cloud_function_task', 'manual__2024-06-09T10:56:47.372616+00:00', '--job-id', '5', '--raw', '--subdir', 'DAGS_FOLDER/dag_reader.py', '--cfg-path', '/tmp/tmp46fzkdk3']
[2024-06-09T10:56:50.842+0000] {standard_task_runner.py:91} INFO - Job 5: Subtask cloud_function_task
[2024-06-09T10:56:50.884+0000] {task_command.py:426} INFO - Running <TaskInstance: metrics_calculator.cloud_function_task manual__2024-06-09T10:56:47.372616+00:00 [running]> on host d7fa402d9e56
[2024-06-09T10:56:50.954+0000] {taskinstance.py:2648} INFO - Exporting env vars: AIRFLOW_CTX_DAG_OWNER='mehdizarria' AIRFLOW_CTX_DAG_ID='metrics_calculator' AIRFLOW_CTX_TASK_ID='cloud_function_task' AIRFLOW_CTX_EXECUTION_DATE='2024-06-09T10:56:47.372616+00:00' AIRFLOW_CTX_TRY_NUMBER='1' AIRFLOW_CTX_DAG_RUN_ID='manual__2024-06-09T10:56:47.372616+00:00'
[2024-06-09T10:56:50.955+0000] {taskinstance.py:430} INFO - ::endgroup::
[2024-06-09T10:56:50.986+0000] {taskinstance.py:441} INFO - ::group::Post task execution logs
[2024-06-09T10:56:50.994+0000] {taskinstance.py:2905} ERROR - Task failed with exception
Traceback (most recent call last):
  File "/home/airflow/.local/lib/python3.12/site-packages/airflow/models/taskinstance.py", line 465, in _execute_task
    result = _execute_callable(context=context, **execute_callable_kwargs)
             ^^^^^^^^^^^^^^^^^^^^^^^^^^^^^^^^^^^^^^^^^^^^^^^^^^^^^^^^^^^^^
  File "/home/airflow/.local/lib/python3.12/site-packages/airflow/models/taskinstance.py", line 432, in _execute_callable
    return execute_callable(context=context, **execute_callable_kwargs)
           ^^^^^^^^^^^^^^^^^^^^^^^^^^^^^^^^^^^^^^^^^^^^^^^^^^^^^^^^^^^^
  File "/home/airflow/.local/lib/python3.12/site-packages/airflow/models/baseoperator.py", line 400, in wrapper
    return func(self, *args, **kwargs)
           ^^^^^^^^^^^^^^^^^^^^^^^^^^^
  File "/home/airflow/.local/lib/python3.12/site-packages/airflow/providers/google/cloud/operators/functions.py", line 466, in execute
    hook = CloudFunctionsHook(
           ^^^^^^^^^^^^^^^^^^^
  File "/home/airflow/.local/lib/python3.12/site-packages/airflow/providers/google/cloud/hooks/functions.py", line 56, in __init__
    super().__init__(
  File "/home/airflow/.local/lib/python3.12/site-packages/airflow/providers/google/common/hooks/base_google.py", line 252, in __init__
    self.extras: dict = self.get_connection(self.gcp_conn_id).extra_dejson
                        ^^^^^^^^^^^^^^^^^^^^^^^^^^^^^^^^^^^^^
  File "/home/airflow/.local/lib/python3.12/site-packages/airflow/hooks/base.py", line 83, in get_connection
    conn = Connection.get_connection_from_secrets(conn_id)
           ^^^^^^^^^^^^^^^^^^^^^^^^^^^^^^^^^^^^^^^^^^^^^^^
  File "/home/airflow/.local/lib/python3.12/site-packages/airflow/models/connection.py", line 519, in get_connection_from_secrets
    raise AirflowNotFoundException(f"The conn_id `{conn_id}` isn't defined")
airflow.exceptions.AirflowNotFoundException: The conn_id `google_cloud_default` isn't defined
[2024-06-09T10:56:50.998+0000] {taskinstance.py:1206} INFO - Marking task as UP_FOR_RETRY. dag_id=metrics_calculator, task_id=cloud_function_task, run_id=manual__2024-06-09T10:56:47.372616+00:00, execution_date=20240609T105647, start_date=20240609T105650, end_date=20240609T105650
[2024-06-09T10:56:51.004+0000] {standard_task_runner.py:110} ERROR - Failed to execute job 5 for task cloud_function_task (The conn_id `google_cloud_default` isn't defined; 318)
[2024-06-09T10:56:51.023+0000] {local_task_job_runner.py:240} INFO - Task exited with return code 1
[2024-06-09T10:56:51.035+0000] {taskinstance.py:3498} INFO - 0 downstream tasks scheduled from follow-on schedule check
[2024-06-09T10:56:51.036+0000] {local_task_job_runner.py:222} INFO - ::endgroup::
